<robot
  name="hsr_jr603">
  
  <link name="world"/>

  <joint name="fixed" type="fixed">
    <parent link="world"/>
    <child link="base_link"/>
	<origin
      xyz="0 0 1"
      rpy="0 0 0" />
  </joint>  

  <link
    name="base_link">
    <inertial>
      <origin
        xyz="-0.04134 0.00084503 -0.24778"
        rpy="0 0 0" />
      <mass
        value="6.73" />
      <inertia
        ixx="0.0054925"
        ixy="0.00089049"
        ixz="-0.002793"
        iyy="0.018137"
        iyz="0.0001034"
        izz="0.012864" />
    </inertial>
    <visual>
      <origin
        xyz="0 0 0"
        rpy="0 0 0" />
      <geometry>
        <mesh
          filename="package://hsr_description/meshes/jr603/base_link.STL" />
      </geometry>
      <material
        name="">
        <color
          rgba="0.3 0.3 0.3 1" />
      </material>
    </visual>
    <collision>
      <origin
        xyz="0 0 0"
        rpy="0 0 0" />
      <geometry>
        <mesh
          filename="package://hsr_description/meshes/jr603/base_link.STL" />
      </geometry>
    </collision>
  </link>
  <link
    name="link1">
    <inertial>
      <origin
        xyz="1.7733E-05 -0.0064938 -0.041624"
        rpy="0 0 0" />
      <mass
        value="2.1859" />
      <inertia
        ixx="0.0032584"
        ixy="-9.8676E-07"
        ixz="3.3951E-09"
        iyy="0.00067224"
        iyz="0.00029829"
        izz="0.0026069" />
    </inertial>
    <visual>
      <origin
        xyz="0 0 0"
        rpy="0 0 0" />
      <geometry>
        <mesh
          filename="package://hsr_description/meshes/jr603/link1.STL" />
      </geometry>
      <material
        name="">
        <color
          rgba="0.6 0.1 0.1 1" />
      </material>
    </visual>
    <collision>
      <origin
        xyz="0 0 0"
        rpy="0 0 0" />
      <geometry>
        <mesh
          filename="package://hsr_description/meshes/jr603/link1.STL" />
      </geometry>
    </collision>
  </link>
  <joint
    name="joint_1"
    type="revolute">
    <origin
      xyz="0 0 0"
      rpy="-9.7175E-17 -2.6052E-16 6.9389E-18" />
    <parent
      link="base_link" />
    <child
      link="link1" />
    <axis
      xyz="0 0 1" />
    <limit
      lower="-2.93"
      upper="2.93"
      effort="28"
      velocity="3.2" />
    <safety_controller
      soft_upper_limit="2.93"
      soft_lower_limit="-2.93"
      k_position="0"
      k_velocity="1.6" />
  </joint>
  <link
    name="link2">
    <inertial>
      <origin
        xyz="0.099213 -0.0060553 0.0030817"
        rpy="0 0 0" />
      <mass
        value="4.4815" />
      <inertia
        ixx="0.0041928"
        ixy="-0.00031232"
        ixz="0.0012463"
        iyy="0.021864"
        iyz="-7.5232E-05"
        izz="0.017709" />
    </inertial>
    <visual>
      <origin
        xyz="0 0 0"
        rpy="0 0 0" />
      <geometry>
        <mesh
          filename="package://hsr_description/meshes/jr603/link2.STL" />
      </geometry>
      <material
        name="">
        <color
          rgba="0.6 0.1 0.1 1" />
      </material>
    </visual>
    <collision>
      <origin
        xyz="0 0 0"
        rpy="0 0 0" />
      <geometry>
        <mesh
          filename="package://hsr_description/meshes/jr603/link2.STL" />
      </geometry>
    </collision>
  </link>
  <joint
    name="joint_2"
    type="revolute">
    <origin
      xyz="0 0.0075 0"
      rpy="-1.5708 -1.5582E-16 -7.8704E-17" />
    <parent
      link="link1" />
    <child
      link="link2" />
    <axis
      xyz="0 0 1" />
    <limit
      lower="-2.7038"
      upper="0"
      effort="28"
      velocity="3.2" />
    <safety_controller
      soft_upper_limit="0"
      soft_lower_limit="-2.60926"
      k_position="0"
      k_velocity="1.6" />
  </joint>
  <link
    name="link3">
    <inertial>
      <origin
        xyz="-0.0076214 -0.019426 0.00038474"
        rpy="0 0 0" />
      <mass
        value="1.6556" />
      <inertia
        ixx="0.0016174"
        ixy="-0.00037566"
        ixz="1.0614E-06"
        iyy="0.00016331"
        iyz="5.1483E-06"
        izz="0.0017103" />
    </inertial>
    <visual>
      <origin
        xyz="0 0 0"
        rpy="0 0 0" />
      <geometry>
        <mesh
          filename="package://hsr_description/meshes/jr603/link3.STL" />
      </geometry>
      <material
        name="">
        <color
          rgba="0.6 0.1 0.1 1" />
      </material>
    </visual>
    <collision>
      <origin
        xyz="0 0 0"
        rpy="0 0 0" />
      <geometry>
        <mesh
          filename="package://hsr_description/meshes/jr603/link3.STL" />
      </geometry>
    </collision>
  </link>
  <joint
    name="joint_3"
    type="revolute">
    <origin
      xyz="0.284 0 -0.0075"
      rpy="7.2825E-17 -9.1181E-17 9.7145E-17" />
    <parent
      link="link2" />
    <child
      link="link3" />
    <axis
      xyz="0 0 1" />
    <limit
      lower="-0.14"
      upper="4.1"
      effort="28"
      velocity="3.2" />
    <safety_controller
      soft_upper_limit="4.1"
      soft_lower_limit="-0.14"
      k_position="0"
      k_velocity="1.6" />
  </joint>
  <link
    name="link4">
    <inertial>
      <origin
        xyz="-0.00030554 0.0029019 0.18537"
        rpy="0 0 0" />
      <mass
        value="1.4831" />
      <inertia
        ixx="0.0019662"
        ixy="-4.1628E-06"
        ixz="-3.4226E-05"
        iyy="0.0013379"
        iyz="8.3826E-05"
        izz="0.00071527" />
    </inertial>
    <visual>
      <origin
        xyz="0 0 0"
        rpy="0 0 0" />
      <geometry>
        <mesh
          filename="package://hsr_description/meshes/jr603/link4.STL" />
      </geometry>
      <material
        name="">
        <color
          rgba="0.6 0.1 0.1 1" />
      </material>
    </visual>
    <collision>
      <origin
        xyz="0 0 0"
        rpy="0 0 0" />
      <geometry>
        <mesh
          filename="package://hsr_description/meshes/jr603/link4.STL" />
      </geometry>-2.541E
    </collision>
  </link>
  <joint
    name="joint_4"
    type="revolute">
    <origin
      xyz="-0.03 0 0"
      rpy="1.5708 7.4106E-16 -2.0931E-17" />
    <parent
      link="link3" />
    <child
      link="link4" />
    <axis
      xyz="0 0 1" />
    <limit
      lower="-2.72"
      upper="2.72"
      effort="28"
      velocity="3.2" />
    <safety_controller
      soft_upper_limit="2.72"
      soft_lower_limit="-2.72"
      k_position="0"
      k_velocity="1.6" />
  </joint>
  <link
    name="link5">
    <inertial>
      <origin
        xyz="4.478E-05 -0.020634 5.7036E-05"
        rpy="0 0 0" />
      <mass
        value="0.37027" />
      <inertia
        ixx="0.0001167"
        ixy="-3.9862E-07"
        ixz="2.858E-08"
        iyy="1.2223E-05"
        iyz="-5.2507E-06"
        izz="0.00010719" />
    </inertial>
    <visual>
      <origin
        xyz="0 0 0"
        rpy="0 0 0" />
      <geometry>
        <mesh
          filename="package://hsr_description/meshes/jr603/link5.STL" />
      </geometry>
      <material
        name="">
        <color
          rgba="0.6 0.1 0.1 1" />
      </material>
    </visual>
    <collision>
      <origin
        xyz="0 0 0"
        rpy="0 0 0" />
      <geometry>
        <mesh
          filename="package://hsr_description/meshes/jr603/link5.STL" />
      </geometry>
    </collision>
  </link>
  <joint
    name="joint_5"
    type="revolute">
    <origin
      xyz="0 0 0.2865"
      rpy="-1.5708 2.0867E-17 -2.541E-17" />
    <parent
      link="link4" />
    <child
      link="link5" />
    <axis
      xyz="0 0 1" />
    <limit
      lower="-1.6580"
      upper="1.6580"
      effort="28"
      velocity="3.2" />
    <safety_controller
      soft_upper_limit="1.6580"
      soft_lower_limit="-1.6580"
      k_position="0"
      k_velocity="1.6" />
  </joint>
  <link
    name="link6">
    <inertial>
      <origin
        xyz="1.1085E-10 1.338E-05 -0.0055759"
        rpy="0 0 0" />
      <mass
        value="0.019515" />
      <inertia
        ixx="1.1281E-07"
        ixy="-5.8474E-14"
        ixz="1.0084E-14"
        iyy="2.8371E-09"
        iyz="1.1946E-08"
        izz="1.1245E-07" />
    </inertial>
    <visual>
      <origin
        xyz="0 0 0"
        rpy="0 0 0" />
      <geometry>
        <mesh
          filename="package://hsr_description/meshes/jr603/link6.STL" />
      </geometry>
      <material
        name="">
        <color
          rgba="0.3 0.3 0.3 1" />
      </material>
    </visual>
    <collision>
      <origin
        xyz="0 0 0"
        rpy="0 0 0" />
      <geometry>
        <mesh
          filename="package://hsr_description/meshes/jr603/link6.STL" />
      </geometry>
    </collision>
  </link>
  <joint
    name="joint_6"
    type="revolute">
    <origin
      xyz="0 -0.0815 0"
      rpy="1.5708 -1.5708 0" />
    <parent
      link="link5" />
    <child
      link="link6" />
    <axis
      xyz="0 0 1" />
    <limit
      lower="-3.141593"
      upper="3.141593"
      effort="28"
      velocity="3.2" />
    <safety_controller
      soft_upper_limit="3.141593"
      soft_lower_limit="-3.141593"
      k_position="0"
      k_velocity="1.6" />
  </joint>

<gazebo>
    <plugin name="gazebo_ros_control" filename="libgazebo_ros_control.so">
      <robotNamespace>/</robotNamespace>
      <robotSimType>gazebo_ros_control/DefaultRobotHWSim</robotSimType>
    </plugin>
  </gazebo>

<gazebo reference="base_link">
	<material>Gazebo/FlatBlack</material>
</gazebo>
<gazebo reference="link1">
	<material>Gazebo/Red</material>
</gazebo>
<gazebo reference="link2">
	<material>Gazebo/Red</material>
</gazebo>
<gazebo reference="link3">
	<material>Gazebo/Red</material>
</gazebo>
<gazebo reference="link4">
	<material>Gazebo/Red</material>
</gazebo>
<gazebo reference="link5">
	<material>Gazebo/Red</material>
</gazebo>
<gazebo reference="link6">
	<material>Gazebo/Black</material>
</gazebo>

  <transmission name="tran1">
    <type>transmission_interface/SimpleTransmission</type>
    <joint name="joint_1">
      <hardwareInterface>PositionJointInterface</hardwareInterface>
    </joint>
    <actuator name="motor1">
      <hardwareInterface>PositionJointInterface</hardwareInterface>
      <mechanicalReduction>1</mechanicalReduction>
    </actuator>
  </transmission>

  <transmission name="tran2">
    <type>transmission_interface/SimpleTransmission</type>
    <joint name="joint_2">
      <hardwareInterface>PositionJointInterface</hardwareInterface>
    </joint>
    <actuator name="motor2">
      <hardwareInterface>PositionJointInterface</hardwareInterface>
      <mechanicalReduction>1</mechanicalReduction>
    </actuator>
  </transmission>

  <transmission name="tran3">
    <type>transmission_interface/SimpleTransmission</type>
    <joint name="joint_3">
      <hardwareInterface>PositionJointInterface</hardwareInterface>
    </joint>
    <actuator name="motor3">
      <hardwareInterface>PositionJointInterface</hardwareInterface>
      <mechanicalReduction>1</mechanicalReduction>
    </actuator>
  </transmission>

  <transmission name="tran4">
    <type>transmission_interface/SimpleTransmission</type>
    <joint name="joint_4">
      <hardwareInterface>PositionJointInterface</hardwareInterface>
    </joint>
    <actuator name="motor4">
      <hardwareInterface>PositionJointInterface</hardwareInterface>
      <mechanicalReduction>1</mechanicalReduction>
    </actuator>
  </transmission>

  <transmission name="tran5">
    <type>transmission_interface/SimpleTransmission</type>
    <joint name="joint_5">
      <hardwareInterface>PositionJointInterface</hardwareInterface>
    </joint>
    <actuator name="motor5">
      <hardwareInterface>PositionJointInterface</hardwareInterface>
      <mechanicalReduction>1</mechanicalReduction>
    </actuator>
  </transmission>

  <transmission name="tran6">
    <type>transmission_interface/SimpleTransmission</type>
    <joint name="joint_6">
      <hardwareInterface>PositionJointInterface</hardwareInterface>
    </joint>
    <actuator name="motor6">
      <hardwareInterface>PositionJointInterface</hardwareInterface>
      <mechanicalReduction>1</mechanicalReduction>
    </actuator>
  </transmission>  

</robot>
